#VRML_SIM R2025a utf8

EXTERNPROTO "https://raw.githubusercontent.com/cyberbotics/webots/R2025a/projects/objects/floors/protos/RectangleArena.proto"

WorldInfo {
}
Viewpoint {
  orientation -0.16918054227883958 -0.23077233919256543 0.9581868667320739 4.571973801744105
  position -0.33048743807418834 5.106015343531941 2.224450172141153
  follow "rectangle arena"
}
Background {
  skyColor [
    0.4 0.7 1
  ]
}
RectangleArena {
  floorSize 5 5
  floorTileSize 1 1
}
Robot {
  translation 0 0 0.15
  children [
    DEF BACK Solid {
      children [
        DEF BACK_BODY Shape {
          appearance PBRAppearance {
            baseColor 0.100023 0.53666 0.0196841
          }
          geometry Mesh {
            url [
              "/home/karsten/Coding/Robotics/Snowplow2025/install/simulation/share/simulation/worlds/../resource/meshes/hyflex/back_collision.stl"
            ]
          }
        }
      ]
      name "solid(5)"
      boundingObject USE BACK_BODY
      physics Physics {
      }
    }
    DEF FRONT Solid {
      children [
        DEF FRONT_BODY Shape {
          appearance PBRAppearance {
            baseColor 0.100023 0.53666 0.0196841
          }
          geometry Mesh {
            url [
              "/home/karsten/Coding/Robotics/Snowplow2025/install/simulation/share/simulation/worlds/../resource/meshes/hyflex/base_link_collision.stl"
            ]
          }
        }
      ]
      boundingObject USE FRONT_BODY
      physics Physics {
      }
    }
    DEF BACK_LEFT HingeJoint {
      jointParameters HingeJointParameters {
        axis 0 1 0
        anchor -0.978237 0.380379 0.0785005
      }
      device [
        RotationalMotor {
          name "back_left_motor"
        }
      ]
      endPoint Solid {
        translation -0.978237 0.380379 0.0785005
        rotation 0 1 0 0
        children [
          DEF WHEEL Shape {
            appearance PBRAppearance {
              baseColor 1 0 0
            }
            geometry Mesh {
              url [
                "../resource/meshes/hyflex/wheel_collision.stl"
              ]
            }
          }
        ]
        name "solid(3)"
        boundingObject USE WHEEL
        physics DEF physics_wh Physics {
        }
      }
    }
    DEF FRONT_LEFT HingeJoint {
      jointParameters HingeJointParameters {
        axis 0 1 0
        anchor -0.2759640000000001 0.380379 0.0785005
      }
      device [
        RotationalMotor {
          name "front_left_motor"
        }
      ]
      endPoint Solid {
        translation -0.2759640000000001 0.380379 0.0785005
        rotation 0 1 0 0
        children [
          DEF WHEEL Shape {
            appearance PBRAppearance {
              baseColor 1 0 0
            }
            geometry Mesh {
              url [
                "../resource/meshes/hyflex/wheel_collision.stl"
              ]
            }
          }
        ]
        name "solid(2)"
        boundingObject USE WHEEL
        physics DEF physics_wh Physics {
        }
      }
    }
    DEF FRONT_RIGHT HingeJoint {
      jointParameters HingeJointParameters {
        axis 0 1 0
        anchor -0.275964 -0.380379 0.0785005
      }
      device [
        RotationalMotor {
          name "front_right_motor"
        }
      ]
      endPoint Solid {
        translation -0.275964 -0.380379 0.0785005
        rotation 0 1 0 0
        children [
          DEF WHEEL Shape {
            appearance PBRAppearance {
              baseColor 1 0 0
            }
            geometry Mesh {
              url [
                "../resource/meshes/hyflex/wheel_collision.stl"
              ]
            }
          }
        ]
        name "solid(1)"
        boundingObject USE WHEEL
        physics DEF physics_wh Physics {
        }
      }
    }
    DEF BACK_RIGHT HingeJoint {
      jointParameters HingeJointParameters {
        axis 0 1 0
        anchor -0.978237 -0.380379 0.0785005
      }
      device [
        RotationalMotor {
          name "back_right_motor"
        }
      ]
      endPoint Solid {
        translation -0.978237 -0.380379 0.0785005
        rotation 0 1 0 0
        children [
          DEF WHEEL Shape {
            appearance PBRAppearance {
              baseColor 1 0 0
            }
            geometry Mesh {
              url [
                "../resource/meshes/hyflex/wheel_collision.stl"
              ]
            }
          }
        ]
        name "solid(4)"
        boundingObject USE WHEEL
        physics DEF physics_wh Physics {
        }
      }
    }
  ]
  name "hyflex"
  physics Physics {
  }
  controller "<extern>"
}
